<?xml version="1.0" ?>
<!-- =================================================================================== -->
<!-- |    This document was autogenerated by xacro from ff6dof.xacro              | -->
<!-- |    EDITING THIS FILE BY HAND IS NOT RECOMMENDED                                 | -->
<!-- =================================================================================== -->
<robot name="ff6dof" xmlns:xacro="http://www.ros.org/wiki/xacro">
  <!-- Include materials -->
  <material name="Red">
    <color rgba="0.8 0.0 0.0 1.0"/>
  </material>
  <material name="Blue">
    <color rgba="0.0 0.0 0.8 1.0"/>
  </material>
  <material name="Green">
    <color rgba="0.0 0.8 0.0 1.0"/>
  </material>
  <material name="Gray">
    <color rgba="0.5 0.5 0.5 1.0"/>
  </material>
  <!-- Constants -->
  <!-- Lengths for the left arm -->
  <!-- Lengths for the left leg -->
  <!-- Lengths for the torso -->
  <!-- ============================================================ -->
  <!--        TORAX LINK: where the arms/legs are placed            -->
  <!-- ============================================================ -->
  <link name="base_link"/>
  <joint name="base_link_fixedjoint" type="fixed">
    <parent link="base_link"/>
    <child link="torso"/>
    <origin rpy="0 0 0" xyz="0 0 0"/>
    <axis xyz="0 0 0"/>
  </joint>
  <link name="torso">
    <visual>
      <origin rpy="0 0 0" xyz=" 0 0 0"/>
      <geometry>
        <box size="0.05 0.2 0.2"/>
      </geometry>
      <material name="Blue"/>
    </visual>
  </link>
  <!-- ============================================================ -->
  <!--        LEFT ARM LINKS                                        -->
  <!-- ============================================================ -->
  <joint name="larm_j1" type="revolute">
    <parent link="torso"/>
    <child link="larm1"/>
    <origin rpy="0 0 0" xyz="0 0.1 0.1"/>
    <axis xyz="1 0 0"/>
    <limit effort="300" lower="-1" upper="2.75" velocity="1"/>
  </joint>
  <link name="larm1">
    <visual>
      <origin rpy="1.570795 0 0" xyz="0 0.1 0"/>
      <geometry>
        <cylinder length="0.2" radius="0.025"/>
      </geometry>
      <material name="Red"/>
    </visual>
  </link>
  <joint name="larm_j2" type="revolute">
    <parent link="larm1"/>
    <child link="larm2"/>
    <origin rpy="0 0 0" xyz="0 0.2 0"/>
    <axis xyz="1 0 0"/>
    <limit effort="300" lower="-2.5" upper="2.5" velocity="1"/>
  </joint>
  <link name="larm2">
    <visual>
      <origin rpy="1.570795 0 0" xyz="0 0.1 0"/>
      <geometry>
        <cylinder length="0.2" radius="0.025"/>
      </geometry>
      <material name="Blue"/>
    </visual>
  </link>
  <joint name="larm_j3" type="revolute">
    <parent link="larm2"/>
    <child link="larm3"/>
    <origin rpy="0 0 0" xyz="0 0.2 0"/>
    <axis xyz="1 0 0"/>
    <limit effort="300" lower="-2.5" upper="2.5" velocity="1"/>
  </joint>
  <link name="larm3">
    <visual>
      <origin rpy="1.570795 0 0" xyz="0 0.025 0"/>
      <geometry>
        <cylinder length="0.05" radius="0.025"/>
      </geometry>
      <material name="Green"/>
    </visual>
  </link>
  <!-- Balls located at joint positions (only for visual purposes) -->
  <joint name="larm1_ball_joint" type="fixed">
    <parent link="larm1"/>
    <child link="larm1_ball"/>
    <origin rpy="0 0 0" xyz="0 0 0"/>
    <axis xyz="0 0 0"/>
  </joint>
  <link name="larm1_ball">
    <visual>
      <origin rpy="0 0 0" xyz="0 0 0"/>
      <geometry>
        <sphere radius="0.03"/>
      </geometry>
      <material name="Gray"/>
    </visual>
  </link>
  <joint name="larm2_ball_joint" type="fixed">
    <parent link="larm2"/>
    <child link="larm2_ball"/>
    <origin rpy="0 0 0" xyz="0 0 0"/>
    <axis xyz="0 0 0"/>
  </joint>
  <link name="larm2_ball">
    <visual>
      <origin rpy="0 0 0" xyz="0 0 0"/>
      <geometry>
        <sphere radius="0.03"/>
      </geometry>
      <material name="Gray"/>
    </visual>
  </link>
  <joint name="larm3_ball_joint" type="fixed">
    <parent link="larm3"/>
    <child link="larm3_ball"/>
    <origin rpy="0 0 0" xyz="0 0 0"/>
    <axis xyz="0 0 0"/>
  </joint>
  <link name="larm3_ball">
    <visual>
      <origin rpy="0 0 0" xyz="0 0 0"/>
      <geometry>
        <sphere radius="0.03"/>
      </geometry>
      <material name="Gray"/>
    </visual>
  </link>
  <!-- ============================================================ -->
  <!--        LEFT LEG LINKS                                        -->
  <!-- ============================================================ -->
  <joint name="lleg_j1" type="revolute">
    <parent link="torso"/>
    <child link="lleg1"/>
    <origin rpy="0 0 0" xyz="0 0.1 -0.1"/>
    <axis xyz="1 0 0"/>
    <limit effort="300" lower="-2.75" upper="1" velocity="1"/>
  </joint>
  <link name="lleg1">
    <visual>
      <origin rpy="1.570795 0 0" xyz="0 0.1 0"/>
      <geometry>
        <cylinder length="0.2" radius="0.025"/>
      </geometry>
      <material name="Red"/>
    </visual>
  </link>
  <joint name="lleg_j2" type="revolute">
    <parent link="lleg1"/>
    <child link="lleg2"/>
    <origin rpy="0 0 0" xyz="0 0.2 0"/>
    <axis xyz="1 0 0"/>
    <limit effort="300" lower="-2.5" upper="2.5" velocity="1"/>
  </joint>
  <link name="lleg2">
    <visual>
      <origin rpy="1.570795 0 0" xyz="0 0.1 0"/>
      <geometry>
        <cylinder length="0.2" radius="0.025"/>
      </geometry>
      <material name="Blue"/>
    </visual>
  </link>
  <joint name="lleg_j3" type="revolute">
    <parent link="lleg2"/>
    <child link="lleg3"/>
    <origin rpy="0 0 0" xyz="0 0.2 0"/>
    <axis xyz="1 0 0"/>
    <limit effort="300" lower="-2.5" upper="2.5" velocity="1"/>
  </joint>
  <link name="lleg3">
    <visual>
      <origin rpy="1.570795 0 0" xyz="0 0.025 0"/>
      <geometry>
        <cylinder length="0.05" radius="0.025"/>
      </geometry>
      <material name="Green"/>
    </visual>
  </link>
  <!-- Balls located at joint positions (only for visual purposes) -->
  <joint name="lleg1_ball_joint" type="fixed">
    <parent link="lleg1"/>
    <child link="lleg1_ball"/>
    <origin rpy="0 0 0" xyz="0 0 0"/>
    <axis xyz="0 0 0"/>
  </joint>
  <link name="lleg1_ball">
    <visual>
      <origin rpy="0 0 0" xyz="0 0 0"/>
      <geometry>
        <sphere radius="0.03"/>
      </geometry>
      <material name="Gray"/>
    </visual>
  </link>
  <joint name="lleg2_ball_joint" type="fixed">
    <parent link="lleg2"/>
    <child link="lleg2_ball"/>
    <origin rpy="0 0 0" xyz="0 0 0"/>
    <axis xyz="0 0 0"/>
  </joint>
  <link name="lleg2_ball">
    <visual>
      <origin rpy="0 0 0" xyz="0 0 0"/>
      <geometry>
        <sphere radius="0.03"/>
      </geometry>
      <material name="Gray"/>
    </visual>
  </link>
  <joint name="lleg3_ball_joint" type="fixed">
    <parent link="lleg3"/>
    <child link="lleg3_ball"/>
    <origin rpy="0 0 0" xyz="0 0 0"/>
    <axis xyz="0 0 0"/>
  </joint>
  <link name="lleg3_ball">
    <visual>
      <origin rpy="0 0 0" xyz="0 0 0"/>
      <geometry>
        <sphere radius="0.03"/>
      </geometry>
      <material name="Gray"/>
    </visual>
  </link>
</robot>

